<?xml version='1.0'?>
<sdf version='1.5'>

	<model name='rrhorizontal'>
		
		<plugin name="set_stiffness_joint1" filename="libmodel_push1.so"/>
		<!-- <plugin name="set_stiffness_joint2" filename="libmodel_push2.so"/> -->
		
		<plugin name="gazebo_ros_control" filename="libgazebo_ros_control.so">
			<robotNamespace>/rrhorizontal</robotNamespace>
		</plugin>
		
		<plugin name="ft_sensor" filename="libgazebo_ros_ft_sensor.so">
			<always_on>true</always_on>
			<updateRate>50.0</updateRate>
			<topicName>ft_sensor_elastic_joint1</topicName>
			<jointName>elastic_joint1</jointName>
		</plugin>
		
		<plugin name="elastic_joint_encoder" filename="libgazebo_ros_joint_state_publisher.so">
			<always_on>true</always_on>
			<topicname>elastic_joint1_encoder</topicname>
			<jointName>elastic_joint1</jointName>
			<updateRate>50.0</updateRate>
		</plugin>
		
		
		<static> false </static>
			
	
		<joint type="fixed" name="fixed">
			<parent> world </parent>
			<child> base_link </child>
			
		</joint>
	
	
		<link name= "base_link">
			<pose> 0 0 0.1 0 0 0</pose>
			<collision name='collision'>
				<geometry>
					<box>
						<size> 1.2 0.2 0.2 </size>
					</box>
				</geometry>
			</collision>
		
			<visual name='visual'>
				<geometry>
					<box>
						<size> 1.2 0.2 0.2 </size>
					</box>
				</geometry>
			</visual>
			<inertial>
				<mass> 1.0 </mass>
				<inertia>
          			<ixx>1</ixx>       <!-- for a box: ixx = 0.083 * mass * (y*y + z*z) -->
          			<ixy>0.0</ixy>         <!-- for a box: ixy = 0 -->
          			<ixz>0.0</ixz>         <!-- for a box: ixz = 0 -->
          			<iyy>1</iyy>       <!-- for a box: iyy = 0.083 * mass * (x*x + z*z) -->
          			<iyz>0.0</iyz>         <!-- for a box: iyz = 0 -->
          			<izz>1</izz>       <!-- for a box: izz = 0.083 * mass * (x*x + y*y) -->
        		</inertia>
        	</inertial>
				
		</link>
		
		<joint type="revolute" name="motor_joint1">
			<pose> -0.45 0 0 0 0 0</pose>
			<child> virtual_link1</child>
			<parent> base_link </parent>
			<axis>
				<xyz> 0 0 1</xyz>
				<dynamics>
					<damping>1.0</damping>
				</dynamics>
			</axis>
			<physics>
				<provide_feedback>true</provide_feedback>
			</physics>
			
		</joint>
			
		<link name="virtual_link1">
			<pose> 1 0 0.3 0 0 0</pose>
			<inertial>
				<mass> 0.1 </mass>
				<inertia>
          			<ixx>1</ixx>       <!-- for a box: ixx = 0.083 * mass * (y*y + z*z) -->
          			<ixy>0.0</ixy>         <!-- for a box: ixy = 0 -->
          			<ixz>0.0</ixz>         <!-- for a box: ixz = 0 -->
          			<iyy>1</iyy>       <!-- for a box: iyy = 0.083 * mass * (x*x + z*z) -->
          			<iyz>0.0</iyz>         <!-- for a box: iyz = 0 -->
          			<izz>1</izz>       <!-- for a box: izz = 0.083 * mass * (x*x + y*y) -->
        		</inertia>
        	</inertial>
		</link>
		
		<joint type="revolute" name="elastic_joint1">
			<pose> -0.45 0 0 0 0 0</pose>
			<child> link1</child>
			<parent> virtual_link1 </parent>
			<axis>
				<xyz> 0 0 1</xyz>
				<dynamics>
					<spring_reference> 0.1 </spring_reference>
					<spring_stiffness> 500 </spring_stiffness>
					<damping> 2.0 </damping>
				</dynamics>
			</axis>
			<physics>
				<provide_feedback>true</provide_feedback>
			</physics>
			
		</joint>
	
	
		
		<link name= "link1">
			<pose> 1 0 0.3 0 0 0</pose>
			<collision name='collision'>
				<geometry>
					<box>
						<size> 1 0.2 0.2 </size>
					</box>
				</geometry>
			</collision>
		
			<visual name='visual'>
				<geometry>
					<box>
						<size> 1 0.2 0.2 </size>
					</box>
				</geometry>
			</visual>
		
			<inertial>
				<mass> 1.0 </mass>
				<inertia>
          			<ixx>1</ixx>       <!-- for a box: ixx = 0.083 * mass * (y*y + z*z) -->
          			<ixy>0.0</ixy>         <!-- for a box: ixy = 0 -->
          			<ixz>0.0</ixz>         <!-- for a box: ixz = 0 -->
          			<iyy>1</iyy>       <!-- for a box: iyy = 0.083 * mass * (x*x + z*z) -->
          			<iyz>0.0</iyz>         <!-- for a box: iyz = 0 -->
          			<izz>1</izz>       <!-- for a box: izz = 0.083 * mass * (x*x + y*y) -->
        		</inertia>
        	</inertial>
				
		</link>
		
		<!--
		<joint type="revolute" name="motor_joint2">
			<pose> -0.45 0 0 0 0 0</pose>
			<child> virtual_link2</child>
			<parent> link1 </parent>
			<axis>
				<xyz> 0 0 1</xyz>
				<dynamics>
					<damping> 1.0 </damping>
				</dynamics>
				<limit>
					<lower>-1.3</lower>
					<upper>1.3</upper>
					<effort> 100 </effort>
					<velocity>50</velocity>
				</limit>
			
			</axis>
			<physics>
				<provide_feedback>true</provide_feedback>
			</physics>
		
		</joint>
		
		<link name="virtual_link2">
			<pose> 1.9 0 0.5 0 0 0</pose>
			<inertial>
				<mass> 0.1 </mass>
				<inertia>
          			<ixx>1</ixx>       <!-- for a box: ixx = 0.083 * mass * (y*y + z*z) -->
          			<ixy>0.0</ixy>         <!-- for a box: ixy = 0 -->
          			<ixz>0.0</ixz>         <!-- for a box: ixz = 0 -->
          			<iyy>1</iyy>       <!-- for a box: iyy = 0.083 * mass * (x*x + z*z) -->
          			<iyz>0.0</iyz>         <!-- for a box: iyz = 0 -->
          			<izz>1</izz>       <!-- for a box: izz = 0.083 * mass * (x*x + y*y) -->
        		</inertia>
        	</inertial>
		</link>
	
		<joint type="revolute" name="elastic_joint2">
			<pose> -0.45 0 0 0 0 0</pose>
			<child> link2</child>
			<parent> virtual_link2 </parent>
			<axis>
				<xyz> 0 0 1</xyz>
				<dynamics>
					<spring_reference> 0.1 </spring_reference>
					<spring_stiffness> 500</spring_stiffness>
					<damping> 2.0 </damping>
				</dynamics>
				<limit>
					<lower>-1.3</lower>
					<upper>1.3</upper>
					<effort> 100 </effort>
					<velocity>50</velocity>
				</limit>
			
			</axis>
			<physics>
				<provide_feedback>true</provide_feedback>
			</physics>
		
		</joint>
		
		<link name= "link2">
			<pose> 1.9 0 0.5 0 0 0</pose>
			<collision name='collision'>
				<geometry>
					<box>
						<size> 1 0.2 0.2 </size>
					</box>
				</geometry>
			</collision>
		
			<visual name='visual'>
				<geometry>
					<box>
						<size> 1 0.2 0.2 </size>
					</box>
				</geometry>
			</visual>
		
			<inertial>
				<mass> 1.0 </mass>
				<inertia>
          			<ixx>1</ixx>       <!-- for a box: ixx = 0.083 * mass * (y*y + z*z) -->
          			<ixy>0.0</ixy>         <!-- for a box: ixy = 0 -->
          			<ixz>0.0</ixz>         <!-- for a box: ixz = 0 -->
          			<iyy>1</iyy>       <!-- for a box: iyy = 0.083 * mass * (x*x + z*z) -->
          			<iyz>0.0</iyz>         <!-- for a box: iyz = 0 -->
          			<izz>1</izz>       <!-- for a box: izz = 0.083 * mass * (x*x + y*y) -->
        		</inertia>
        	</inertial>
				
		</link>
	
	-->
	
	</model>
</sdf>