<?xml version="1.0" ?>
<robot name="rrhorizontal">
     
     
     <link name="world"/>
     
  	 <joint name="base_link_to_gazebo" type="fixed">
		<parent link="world"/>
		<child link="base_link"/>
	 </joint>
  
  
 	<link name="base_link">
    	<inertial>
      		<mass value="1.0"/>
      		<origin rpy="0  0  0" xyz="0   0   0.1"/>
      		<inertia ixx="1.0" ixy="0" ixz="0" iyy="1.0" iyz="0" izz="1.0"/>
    	</inertial>
    	<collision>
      		<origin rpy="0  0  0" xyz="0   0   0.1"/>
      		<geometry>
        		<box size="1.2 0.2 0.2"/>
      		</geometry>
    	</collision>
    	<visual>
      		<origin rpy="0  0  0" xyz="0   0   0.1"/>
      		<geometry>
        		<box size="1.2 0.2 0.2"/>
      		</geometry>
    	</visual>
  	</link>
  	
  	<joint name="motor_joint1" type="continuous">
  		<parent link="base_link"/>
  		<child link="virtual_link1"/>
  		<origin rpy="0  0  0" xyz="0.55  0    0.3"/>
  		<axis xyz="0  0  1"/>
  	</joint>
  	
  	<link name="virtual_link1">
  		<inertial>
      		<mass value="1.0"/>
      		<origin rpy="0  0  0" xyz="0   0   0.1"/>
      		<inertia ixx="1.0" ixy="0" ixz="0" iyy="1.0" iyz="0" izz="1.0"/>
    	</inertial>
    </link>
  	
  	
  	<joint name="elastic_joint1" type="continuous">
    	<parent link="virtual_link1"/>
    	<child link="link1"/>
    	<origin rpy="0  0  0" xyz="0.55  0    0.3"/>
    	<axis xyz="0  0  1"/>
  	</joint>
  	
  	
  
  	<link name="link1">
    	<inertial>
      		<mass value="1.0"/>
      		<origin rpy="0  0  0" xyz="0.45  0    0"/>
      		<inertia ixx="1" ixy="0.0" ixz="0.0" iyy="1" iyz="0.0" izz="1"/>
    	</inertial>
    	<collision>
      		<origin rpy="0  0  0" xyz="0.45  0    0"/>
      		<geometry>
        		<box size="1 0.2 0.2"/>
      		</geometry>
    	</collision>
    	<visual>
      		<origin rpy="0  0  0" xyz="0.45  0    0"/>
      		<geometry>
        		<box size="1 0.2 0.2"/>
      		</geometry>
    	</visual>
  	</link>
  	
  	<!--
  	<joint name="motor_joint2" type="revolute">
    	<parent link="link1"/>
    	<child link="virtual_link2"/>
    	<origin rpy="0  0  0" xyz="0.9  0   0.2"/>
    	<axis xyz="0  0  1"/>
    	<limit effort="100" lower="-1.3" upper="1.3" velocity="50"/>
  	</joint>
  	
  	<link name="virtual_link2">
  		<inertial>
      		<mass value="1.0"/>
      		<origin rpy="0  0  0" xyz="0   0   0.1"/>
      		<inertia ixx="1.0" ixy="0" ixz="0" iyy="1.0" iyz="0" izz="1.0"/>
    	</inertial>
    </link>
  	
  
  
  	<joint name="elastic_joint2" type="revolute">
    	<parent link="virtual_link2"/>
    	<child link="link2"/>
    	<origin rpy="0  0  0" xyz="0.9  0   0.2"/>
    	<axis xyz="0  0  1"/>
    	<limit effort="100" lower="-1.3" upper="1.3" velocity="50"/>
  	</joint>
  	
  	
  	
  	
	<link name="link2">
    		<inertial>
      			<mass value="1.0"/>
      			<origin rpy="0  0  0" xyz="0.45  0    0"/>
      			<inertia ixx="1" ixy="0.0" ixz="0.0" iyy="1" iyz="0.0" izz="1"/>
    		</inertial>
    		<collision >
      			<origin rpy="0  0  0" xyz="0.45  0    0"/>
      			<geometry>
        			<box size="1 0.2 0.2"/>
      			</geometry>
    		</collision>
    		<visual>
      			<origin rpy="0  0  0" xyz="0.45  0    0"/>
      			<geometry>
        			<box size="1 0.2 0.2"/>
      			</geometry>
    		</visual>
  	</link>
  -->
  	<gazebo>
		<plugin name="gazebo_ros_control" filename="libgazebo_ros_control.so">
			<robotNamespace>/rrhorizontal</robotNamespace>
		</plugin> 
		
		<plugin name="ft_sensor" filename="libgazebo_ros_ft_sensor.so">
			<always_on>true</always_on>
			<updateRate>50.0</updateRate>
			<topicName>ft_sensor_joint1</topicName>
			<jointName>elastic_joint1</jointName>
		</plugin>
		
		<plugin name="set_stiffness_joint1" filename="libmodel_push1.so"/>
		<!-- <plugin name="set_stiffness_joint2" filename="libmodel_push2.so"/> -->
		
		<plugin name="elastic_joint_encoder" filename="libgazebo_ros_joint_state_publisher.so">
			<always_on>true</always_on>
			<topicName>elastic_joint1_encoder</topicName>
			<jointName>elastic_joint1</jointName>
			<updateRate>50.0</updateRate>
		</plugin>
		
    
	</gazebo>
		
	
	<transmission name="tran1">
		<type>transmission_interface/SimpleTransmission</type>
		<joint name="motor_joint1">
			<hardwareInterface>hardware_interface/EffortJointInterface</hardwareInterface>
		</joint>
		<actuator name="motor1">
      		<hardwareInterface>hardware_interface/EffortJointInterface</hardwareInterface>
      		<mechanicalReduction>1</mechanicalReduction>
    	</actuator>
	</transmission>
	
	<transmission name="tran2">
		<type>transmission_interface/SimpleTransmission</type>
		<joint name="elastic_joint1">
			<hardwareInterface>hardware_interface/EffortJointInterface</hardwareInterface>
		</joint>
		<actuator name="motor2">
      		<hardwareInterface>hardware_interface/EffortJointInterface</hardwareInterface>
      		<mechanicalReduction>1</mechanicalReduction>
    	</actuator>
	</transmission>

</robot>
